---
title: "Python Error Handling"
weight: 2
# bookFlatSection: false
# bookToc: true
# bookHidden: false
# bookCollapseSection: false
# bookComments: false
# bookSearchExclude: false
---

# Python Error Handling

Error handling is a crucial aspect of programming that enables developers to manage and respond to exceptional conditions that occur during the execution of a program. In Python, error handling is accomplished through the use of exceptions, which are special objects used to signal that an error has occurred. This approach not only helps in identifying and managing errors but also ensures that programs can recover from them gracefully.

## Historical Context

The concept of error handling and exceptions dates back to the early days of programming languages, with the introduction of structured programming languages in the 1970s and 1980s. Languages such as C introduced the concept of error codes, while more advanced languages like Ada and Java incorporated more sophisticated exception handling mechanisms. Python adopted an exception-based approach that has become a cornerstone of its error handling strategy. Over the years, Python’s exception handling has evolved, with significant improvements introduced in Python 2.x and Python 3.x to enhance clarity and control.

## Exceptions in Python

### Understanding Exceptions

Exceptions are special objects in Python that signal the occurrence of an error. When an error occurs, Python creates an exception object, which can be caught and handled by the program. Exceptions provide a mechanism for detecting and responding to errors, enabling the program to continue executing or to terminate gracefully.

Here’s a simple example demonstrating an exception:

```python
try:
    # Code that might raise an exception
    result = 10 / 0
except ZeroDivisionError:
    # Handling the exception
    print("Error: Division by zero is not allowed.")
```

In this example, the `try` block contains code that may raise an exception, and the `except` block specifies how to handle a `ZeroDivisionError`. When a division by zero occurs, Python raises a `ZeroDivisionError`, and the program prints an error message.

### The try-except Block

The `try-except` block is the fundamental structure for handling exceptions in Python. It consists of a `try` block that contains code prone to errors and one or more `except` blocks that handle specific exceptions.

Here’s a more detailed example:

```python
def divide_numbers(a, b):
    try:
        result = a / b
    except ZeroDivisionError:
        print("Error: Cannot divide by zero.")
        return None
    except TypeError:
        print("Error: Both arguments must be numbers.")
        return None
    else:
        return result
    finally:
        print("Execution completed.")

# Test cases
print(divide_numbers(10, 2))  # Output: 5.0
print(divide_numbers(10, 0))  # Output: Error: Cannot divide by zero. Execution completed.
print(divide_numbers(10, "a"))  # Output: Error: Both arguments must be numbers. Execution completed.
```

In this example, the `divide_numbers` function uses a `try-except` block to handle `ZeroDivisionError` and `TypeError`. The `else` block executes if no exceptions occur, and the `finally` block always executes, regardless of whether an exception was raised.

### Raising Exceptions

Sometimes, you may need to raise exceptions manually to indicate that an error condition has occurred. This is done using the `raise` statement, which can be used to raise built-in or custom exceptions.

Here’s an example of raising an exception:

```python
def check_age(age):
    if age < 0:
        raise ValueError("Age cannot be negative.")
    elif age < 18:
        raise PermissionError("You must be at least 18 years old.")
    else:
        print("Age is valid.")

# Test cases
try:
    check_age(-5)
except ValueError as ve:
    print(ve)
except PermissionError as pe:
    print(pe)

try:
    check_age(16)
except ValueError as ve:
    print(ve)
except PermissionError as pe:
    print(pe)

try:
    check_age(20)
except ValueError as ve:
    print(ve)
except PermissionError as pe:
    print(pe)
```

In this example, the `check_age` function raises `ValueError` or `PermissionError` based on the input. The `try-except` blocks catch and handle these exceptions, demonstrating how to manually raise and handle exceptions.

## Custom Exceptions

Python allows the creation of custom exception classes, which can be used to represent specific error conditions unique to an application. Custom exceptions provide a way to distinguish between different types of errors and to handle them appropriately.

Here’s an example of creating and using custom exceptions:

```python
class CustomError(Exception):
    def __init__(self, message):
        super().__init__(message)
        self.message = message

class InvalidInputError(CustomError):
    pass

class OperationFailedError(CustomError):
    pass

def perform_operation(value):
    if value < 0:
        raise InvalidInputError("Invalid input: negative value.")
    elif value > 100:
        raise OperationFailedError("Operation failed: value too large.")
    else:
        print("Operation successful.")

# Test cases
try:
    perform_operation(-10)
except InvalidInputError as ie:
    print(ie)

try:
    perform_operation(150)
except OperationFailedError as ofe:
    print(ofe)

try:
    perform_operation(50)
except (InvalidInputError, OperationFailedError) as e:
    print(e)
```

In this example, `CustomError` is a base class for custom exceptions, and `InvalidInputError` and `OperationFailedError` are derived classes. The `perform_operation` function raises these custom exceptions based on the input value, demonstrating how to define and use custom exceptions.

## Exception Hierarchy

Python’s exception hierarchy is structured in a way that allows for flexible and hierarchical error handling. At the top of this hierarchy is the `BaseException` class, which is the root of all exception classes. It is followed by `Exception`, which is the base class for most built-in exceptions, and then more specific exception classes such as `IOError`, `ValueError`, and `TypeError`.

Understanding this hierarchy is important for effective error handling, as you can catch exceptions at various levels of specificity. For example:

```python
try:
    # Code that might raise an exception
    pass
except Exception as e:
    # Handle all exceptions that derive from Exception
    print(f"An error occurred: {e}")
```

This example shows how to catch all exceptions that are derived from the `Exception` class, which includes most built-in exceptions.

## Best Practices

Effective error handling involves adhering to best practices to ensure that your code is robust and maintainable. Some best practices include:

1. **Catch Specific Exceptions:** Avoid catching generic exceptions unless necessary. Catching specific exceptions allows for more precise handling of error conditions.

2. **Use Custom Exceptions:** Define custom exceptions for specific error conditions to improve code readability and maintainability.

3. **Avoid Empty Except Blocks:** Empty except blocks can mask errors and make debugging difficult. Always handle exceptions explicitly or log them for further analysis.

4. **Use Finally for Cleanup:** Use the `finally` block to perform cleanup actions, such as closing files or releasing resources, regardless of whether an exception was raised.

5. **Log Exceptions:** Consider logging exceptions to provide detailed information about errors that occur, which can be helpful for debugging and monitoring.

## Mathematical Additions

Error handling often involves understanding how to handle errors related to mathematical operations. For instance, division by zero, overflow, and invalid mathematical operations can raise exceptions that need to be managed.

Consider the following example involving mathematical operations:

```python
def safe_divide(a, b):
    try:
        result = a / b
    except ZeroDivisionError:
        print("Error: Cannot divide by zero.")
        return None
    except OverflowError:
        print("Error: Result is too large.")
        return None
    return result

print(safe_divide(10, 2))  # Output: 5.0
print(safe_divide(10, 0))  # Output: Error: Cannot divide by zero.
```

In this example, `safe_divide` handles both `ZeroDivisionError` and `OverflowError`, demonstrating how to manage mathematical errors effectively.